<?xml version="1.0" encoding="UTF-8"?>
<robot xmlns:xacro="http://wiki.ros.org/xacro">

  <xacro:include filename="$(find nav_mecanum_description)/urdf/common.xacro" />

  <xacro:macro name="nav_mecanum" params="prefix parent *origin">
    <!-- LINKS -->
    <!-- base link -->
    <link name="${prefix}base_link">
      <!-- Default inertial for Gazebo/Ingnition - copy and edit block from 'common.xacro'
           to get more realistic behaviour-->
      <xacro:default_inertial/>
      <visual>
        <origin xyz="0 0 0" rpy="0 0 0" />
        <geometry>
          <box size="0.6 1 0.2"/>
<!--           <mesh filename="package://nav_mecanum_description/meshes/nav_mecanum/visual/base_link.dae" /> -->
        </geometry>
      </visual>
      <collision>
        <origin xyz="0 0 0" rpy="0 0 0" />
        <geometry>
          <box size="0.6 1 0.2"/>
<!--           <mesh filename="package://nav_mecanum_description/meshes/nav_mecanum/collision/base_link.stl" /> -->
        </geometry>
      </collision>
    </link>
    <!-- link 1 -->
    <link name="${prefix}link1">
      <!-- Default inertial for Gazebo/Ingnition - copy and edit block from 'common.xacro'
           to get more realistic behaviour-->
      <xacro:default_inertial/>
      <visual>
        <origin xyz="0 0 0" rpy="0 0 0" />
        <geometry>
          <cylinder length="0.1" radius="0.2" />
<!--           <mesh filename="package://nav_mecanum_description/meshes/nav_mecanum/visual/link1.dae" /> -->
        </geometry>
      </visual>
      <collision>
        <origin xyz="0 0 0" rpy="0 0 0" />
        <geometry>
          <cylinder length="0.1" radius="0.2" />
<!--           <mesh filename="package://nav_mecanum_description/meshes/nav_mecanum/collision/link1.stl" /> -->
        </geometry>
      </collision>
    </link>
    <!-- link 2 -->
    <link name="${prefix}link2">
      <!-- Default inertial for Gazebo/Ingnition - copy and edit block from 'common.xacro'
           to get more realistic behaviour-->
      <xacro:default_inertial/>
      <visual>
        <origin xyz="0 0 0" rpy="0 0 0" />
        <geometry>
          <cylinder length="0.1" radius="0.2" />
<!--           <mesh filename="package://nav_mecanum_description/meshes/nav_mecanum/visual/link2.dae" /> -->
        </geometry>
      </visual>
      <collision>
        <origin xyz="0 0 0" rpy="0 0 0" />
        <geometry>
          <cylinder length="0.1" radius="0.2" />
<!--           <mesh filename="package://nav_mecanum_description/meshes/nav_mecanum/collision/link2.stl"  /> -->
        </geometry>
      </collision>
    </link>
    <!-- link 3 -->
    <link name="${prefix}link3">
      <!-- Default inertial for Gazebo/Ingnition - copy and edit block from 'common.xacro'
           to get more realistic behaviour-->
      <xacro:default_inertial/>
      <visual>
        <origin xyz="0 0 0" rpy="0 0 0" />
        <geometry>
          <cylinder length="0.1" radius="0.2" />
<!--           <mesh filename="package://nav_mecanum_description/meshes/nav_mecanum/visual/link3.dae" /> -->
        </geometry>
      </visual>
      <collision>
        <origin xyz="0 0 0" rpy="0 0 0" />
        <geometry>
          <cylinder length="0.1" radius="0.2" />
<!--           <mesh filename="package://nav_mecanum_description/meshes/nav_mecanum/collision/link3.stl"  /> -->
        </geometry>
      </collision>
    </link>
    <!-- link 4 -->
    <link name="${prefix}link4">
      <!-- Default inertial for Gazebo/Ingnition - copy and edit block from 'common.xacro'
           to get more realistic behaviour-->
      <xacro:default_inertial/>
      <visual>
        <origin xyz="0 0 0" rpy="0 0 0" />
        <geometry>
          <cylinder length="0.1" radius="0.2" />
<!--           <mesh filename="package://nav_mecanum_description/meshes/nav_mecanum/visual/link4.dae" /> -->
        </geometry>
      </visual>
      <collision>
        <origin xyz="0 0 0" rpy="0 0 0" />
        <geometry>
          <cylinder length="0.1" radius="0.2" />
<!--           <mesh filename="package://nav_mecanum_description/meshes/nav_mecanum/collision/link4.stl"  /> -->
        </geometry>
      </collision>
    </link>
    <!-- END LINKS -->

    <!-- JOINTS -->
    <!-- base_joint fixes base_link to the environment -->
    <joint name="${prefix}base_joint" type="fixed">
      <xacro:insert_block name="origin" />
      <parent link="${parent}" />
      <child link="${prefix}base_link" />
    </joint>
    <!-- joint 1 -->
    <joint name="${prefix}left_front_wheel_joint" type="continuous">
      <origin xyz="0.5 -0.5 0" rpy="0 ${pi/2} 0" />
      <parent link="${prefix}base_link" />
      <child link="${prefix}link1" />
      <axis xyz="0 0 1" />
    </joint>
    <!-- joint 2 -->
    <joint name="${prefix}left_rear_wheel_joint" type="continuous">
      <origin xyz="-0.5 -0.5 0" rpy="0 ${pi/2} 0" />
      <parent link="${prefix}base_link" />
      <child link="${prefix}link2" />
      <axis xyz="0 0 1" />
    </joint>
    <!-- joint 3 -->
    <joint name="${prefix}right_front_wheel_joint" type="continuous">
      <origin xyz="0.5 0.5 0" rpy="0 ${pi/2} 0" />
      <parent link="${prefix}base_link" />
      <child link="${prefix}link3" />
      <axis xyz="0 0 1" />
    </joint>
    <!-- joint 4 -->
    <joint name="${prefix}right_rear_wheel_joint" type="continuous">
      <origin xyz="-0.5 0.5 0" rpy="0 ${pi/2} 0" />
      <parent link="${prefix}base_link" />
      <child link="${prefix}link4" />
      <axis xyz="0 0 1" />
    </joint>

  </xacro:macro>
</robot>
